Workbook

Sheet KECAMATAN
A1: LAPORAN HARIAN UPT / KECAMATAN
A2: HARI INI | B2: =CHOOSE(WEEKDAY(TODAY()),"Minggu","Senin","Selasa","Rabu","Kamis","Jumat","Sabtu") | C2: TANGGAL HARI INI | D2: =TODAY() | E2: PERIODE DATA | F2: 1 Januari - 31 Desember 2026
A3: INPUT LANGSUNG DI TABEL INI. KLIK DROPDOWN TANGGAL DI SEL A6, hapus centang Pilih Semua, lalu pilih tanggal 1 sampai akhir bulan.
A5: FILTER TANGGAL ↓ | B5: Wilayah | C5: Petugas | D5: Target | E5: Realisasi | G5: Capaian | H5: Catatan
A6: Tanggal | B6: UPT / Kecamatan | C6: Jumlah Petugas | D6: Target WP | E6: Jumlah SPPT | F6: Jumlah RP | G6: Persentase | H6: Keterangan
A7: 46023 | B7: UPT I | C7: =SUM(C8:C10) | D7: =SUM(D8:D10) | E7: =SUM(E8:E10) | F7: =SUM(F8:F10) | G7: =IFERROR(E7/D7,0) | H7: Total UPT I
A8: 46023 | B8: Medan Amplas | C8: 0 | D8: 0 | E8: 0 | F8: 0 | G8: =IFERROR(E8/D8,0)
A9: 46023 | B9: Medan Area | C9: 0 | D9: 0 | E9: 0 | F9: 0 | G9: =IFERROR(E9/D9,0)
A10: 46023 | B10: Medan Kota | C10: 0 | D10: 0 | E10: 0 | F10: 0 | G10: =IFERROR(E10/D10,0)
A11: 46023 | B11: UPT II | C11: =SUM(C12:C14) | D11: =SUM(D12:D14) | E11: =SUM(E12:E14) | F11: =SUM(F12:F14) | G11: =IFERROR(E11/D11,0) | H11: Total UPT II
A12: 46023 | B12: Medan Tembung | C12: 0 | D12: 0 | E12: 0 | F12: 0 | G12: =IFERROR(E12/D12,0)
A13: 46023 | B13: Medan Perjuangan | C13: 0 | D13: 0 | E13: 0 | F13: 0 | G13: =IFERROR(E13/D13,0)
A14: 46023 | B14: Medan Denai | C14: 0 | D14: 0 | E14: 0 | F14: 0 | G14: =IFERROR(E14/D14,0)
A15: 46023 | B15: UPT III | C15: =SUM(C16:C18) | D15: =SUM(D16:D18) | E15: =SUM(E16:E18) | F15: =SUM(F16:F18) | G15: =IFERROR(E15/D15,0) | H15: Total UPT III
A16: 46023 | B16: Medan Sunggal | C16: 0 | D16: 0 | E16: 0 | F16: 0 | G16: =IFERROR(E16/D16,0)
A17: 46023 | B17: Medan Petisah | C17: 0 | D17: 0 | E17: 0 | F17: 0 | G17: =IFERROR(E17/D17,0)
A18: 46023 | B18: Medan Helvetia | C18: 0 | D18: 0 | E18: 0 | F18: 0 | G18: =IFERROR(E18/D18,0)
A19: 46023 | B19: UPT IV | C19: =SUM(C20:C22) | D19: =SUM(D20:D22) | E19: =SUM(E20:E22) | F19: =SUM(F20:F22) | G19: =IFERROR(E19/D19,0) | H19: Total UPT IV
A20: 46023 | B20: Medan Barat | C20: 0 | D20: 0 | E20: 0 | F20: 0 | G20: =IFERROR(E20/D20,0)
A21: 46023 | B21: Medan Timur | C21: 0 | D21: 0 | E21: 0 | F21: 0 | G21: =IFERROR(E21/D21,0)
A22: 46023 | B22: Medan Deli | C22: 0 | D22: 0 | E22: 0 | F22: 0 | G22: =IFERROR(E22/D22,0)
A23: 46023 | B23: UPT V | C23: =SUM(C24:C26) | D23: =SUM(D24:D26) | E23: =SUM(E24:E26) | F23: =SUM(F24:F26) | G23: =IFERROR(E23/D23,0) | H23: Total UPT V
A24: 46023 | B24: Medan Baru | C24: 0 | D24: 0 | E24: 0 | F24: 0 | G24: =IFERROR(E24/D24,0)
A25: 46023 | B25: Medan Polonia | C25: 0 | D25: 0 | E25: 0 | F25: 0 | G25: =IFERROR(E25/D25,0)
A26: 46023 | B26: Medan Maimun | C26: 0 | D26: 0 | E26: 0 | F26: 0 | G26: =IFERROR(E26/D26,0)
A27: 46023 | B27: UPT VI | C27: =SUM(C28:C30) | D27: =SUM(D28:D30) | E27: =SUM(E28:E30) | F27: =SUM(F28:F30) | G27: =IFERROR(E27/D27,0) | H27: Total UPT VI
A28: 46023 | B28: Medan Johor | C28: 0 | D28: 0 | E28: 0 | F28: 0 | G28: =IFERROR(E28/D28,0)
A29: 46023 | B29: Medan Selayang | C29: 0 | D29: 0 | E29: 0 | F29: 0 | G29: =IFERROR(E29/D29,0)
A30: 46023 | B30: Medan Tuntungan | C30: 0 | D30: 0 | E30: 0 | F30: 0 | G30: =IFERROR(E30/D30,0)
A31: 46023 | B31: UPT VII | C31: =SUM(C32:C34) | D31: =SUM(D32:D34) | E31: =SUM(E32:E34) | F31: =SUM(F32:F34) | G31: =IFERROR(E31/D31,0) | H31: Total UPT VII
A32: 46023 | B32: Medan Belawan | C32: 0 | D32: 0 | E32: 0 | F32: 0 | G32: =IFERROR(E32/D32,0)
A33: 46023 | B33: Medan Marelan | C33: 0 | D33: 0 | E33: 0 | F33: 0 | G33: =IFERROR(E33/D33,0)
A34: 46023 | B34: Medan Labuhan | C34: 0 | D34: 0 | E34: 0 | F34: 0 | G34: =IFERROR(E34/D34,0)
A35: 46023 | B35: GRAND TOTAL | C35: =SUM(C7,C11,C15,C19,C23,C27,C31) | D35: =SUM(D7,D11,D15,D19,D23,D27,D31) | E35: =SUM(E7,E11,E15,E19,E23,E27,E31) | F35: =SUM(F7,F11,F15,F19,F23,F27,F31) | G35: =IFERROR(E35/D35,0) | H35: Total Harian
A36: 46024 | B36: UPT I | C36: =SUM(C37:C39) | D36: =SUM(D37:D39) | E36: =SUM(E37:E39) | F36: =SUM(F37:F39) | G36: =IFERROR(E36/D36,0) | H36: Total UPT I
A37: 46024 | B37: Medan Amplas | C37: 0 | D37: 0 | E37: 0 | F37: 0 | G37: =IFERROR(E37/D37,0)
A38: 46024 | B38: Medan Area | C38: 0 | D38: 0 | E38: 0 | F38: 0 | G38: =IFERROR(E38/D38,0)
A39: 46024 | B39: Medan Kota | C39: 0 | D39: 0 | E39: 0 | F39: 0 | G39: =IFERROR(E39/D39,0)
A40: 46024 | B40: UPT II | C40: =SUM(C41:C43) | D40: =SUM(D41:D43) | E40: =SUM(E41:E43) | F40: =SUM(F41:F43) | G40: =IFERROR(E40/D40,0) | H40: Total UPT II
A41: 46024 | B41: Medan Tembung | C41: 0 | D41: 0 | E41: 0 | F41: 0 | G41: =IFERROR(E41/D41,0)
...

Sheet SUMBER DATA
A1: SUMBER DATA OTOMATIS
A2: Data pada sheet ini mengikuti input di KECAMATAN secara otomatis. Input tetap dilakukan di sheet KECAMATAN.
A4: Tanggal | B4: UPT | C4: Kecamatan | D4: Jumlah Petugas | E4: Target WP | F4: Jumlah SPPT | G4: Jumlah RP | H4: Keterangan
A5: 46023 | B5: UPT I | C5: Medan Amplas | D5: =IF(KECAMATAN!C8="","",KECAMATAN!C8) | E5: =IF(KECAMATAN!D8="","",KECAMATAN!D8) | F5: =IF(KECAMATAN!E8="","",KECAMATAN!E8) | G5: =IF(KECAMATAN!F8="","",KECAMATAN!F8) | H5: =IF(KECAMATAN!H8="","",KECAMATAN!H8)
A6: 46023 | B6: UPT I | C6: Medan Area | D6: =IF(KECAMATAN!C9="","",KECAMATAN!C9) | E6: =IF(KECAMATAN!D9="","",KECAMATAN!D9) | F6: =IF(KECAMATAN!E9="","",KECAMATAN!E9) | G6: =IF(KECAMATAN!F9="","",KECAMATAN!F9) | H6: =IF(KECAMATAN!H9="","",KECAMATAN!H9)
A7: 46023 | B7: UPT I | C7: Medan Kota | D7: =IF(KECAMATAN!C10="","",KECAMATAN!C10) | E7: =IF(KECAMATAN!D10="","",KECAMATAN!D10) | F7: =IF(KECAMATAN!E10="","",KECAMATAN!E10) | G7: =IF(KECAMATAN!F10="","",KECAMATAN!F10) | H7: =IF(KECAMATAN!H10="","",KECAMATAN!H10)
A8: 46023 | B8: UPT II | C8: Medan Tembung | D8: =IF(KECAMATAN!C12="","",KECAMATAN!C12) | E8: =IF(KECAMATAN!D12="","",KECAMATAN!D12) | F8: =IF(KECAMATAN!E12="","",KECAMATAN!E12) | G8: =IF(KECAMATAN!F12="","",KECAMATAN!F12) | H8: =IF(KECAMATAN!H12="","",KECAMATAN!H12)
A9: 46023 | B9: UPT II | C9: Medan Perjuangan | D9: =IF(KECAMATAN!C13="","",KECAMATAN!C13) | E9: =IF(KECAMATAN!D13="","",KECAMATAN!D13) | F9: =IF(KECAMATAN!E13="","",KECAMATAN!E13) | G9: =IF(KECAMATAN!F13="","",KECAMATAN!F13) | H9: =IF(KECAMATAN!H13="","",KECAMATAN!H13)
A10: 46023 | B10: UPT II | C10: Medan Denai | D10: =IF(KECAMATAN!C14="","",KECAMATAN!C14) | E10: =IF(KECAMATAN!D14="","",KECAMATAN!D14) | F10: =IF(KECAMATAN!E14="","",KECAMATAN!E14) | G10: =IF(KECAMATAN!F14="","",KECAMATAN!F14) | H10: =IF(KECAMATAN!H14="","",KECAMATAN!H14)
A11: 46023 | B11: UPT III | C11: Medan Sunggal | D11: =IF(KECAMATAN!C16="","",KECAMATAN!C16) | E11: =IF(KECAMATAN!D16="","",KECAMATAN!D16) | F11: =IF(KECAMATAN!E16="","",KECAMATAN!E16) | G11: =IF(KECAMATAN!F16="","",KECAMATAN!F16) | H11: =IF(KECAMATAN!H16="","",KECAMATAN!H16)
A12: 46023 | B12: UPT III | C12: Medan Petisah | D12: =IF(KECAMATAN!C17="","",KECAMATAN!C17) | E12: =IF(KECAMATAN!D17="","",KECAMATAN!D17) | F12: =IF(KECAMATAN!E17="","",KECAMATAN!E17) | G12: =IF(KECAMATAN!F17="","",KECAMATAN!F17) | H12: =IF(KECAMATAN!H17="","",KECAMATAN!H17)
A13: 46023 | B13: UPT III | C13: Medan Helvetia | D13: =IF(KECAMATAN!C18="","",KECAMATAN!C18) | E13: =IF(KECAMATAN!D18="","",KECAMATAN!D18) | F13: =IF(KECAMATAN!E18="","",KECAMATAN!E18) | G13: =IF(KECAMATAN!F18="","",KECAMATAN!F18) | H13: =IF(KECAMATAN!H18="","",KECAMATAN!H18)
A14: 46023 | B14: UPT IV | C14: Medan Barat | D14: =IF(KECAMATAN!C20="","",KECAMATAN!C20) | E14: =IF(KECAMATAN!D20="","",KECAMATAN!D20) | F14: =IF(KECAMATAN!E20="","",KECAMATAN!E20) | G14: =IF(KECAMATAN!F20="","",KECAMATAN!F20) | H14: =IF(KECAMATAN!H20="","",KECAMATAN!H20)
A15: 46023 | B15: UPT IV | C15: Medan Timur | D15: =IF(KECAMATAN!C21="","",KECAMATAN!C21) | E15: =IF(KECAMATAN!D21="","",KECAMATAN!D21) | F15: =IF(KECAMATAN!E21="","",KECAMATAN!E21) | G15: =IF(KECAMATAN!F21="","",KECAMATAN!F21) | H15: =IF(KECAMATAN!H21="","",KECAMATAN!H21)
A16: 46023 | B16: UPT IV | C16: Medan Deli | D16: =IF(KECAMATAN!C22="","",KECAMATAN!C22) | E16: =IF(KECAMATAN!D22="","",KECAMATAN!D22) | F16: =IF(KECAMATAN!E22="","",KECAMATAN!E22) | G16: =IF(KECAMATAN!F22="","",KECAMATAN!F22) | H16: =IF(KECAMATAN!H22="","",KECAMATAN!H22)
A17: 46023 | B17: UPT V | C17: Medan Baru | D17: =IF(KECAMATAN!C24="","",KECAMATAN!C24) | E17: =IF(KECAMATAN!D24="","",KECAMATAN!D24) | F17: =IF(KECAMATAN!E24="","",KECAMATAN!E24) | G17: =IF(KECAMATAN!F24="","",KECAMATAN!F24) | H17: =IF(KECAMATAN!H24="","",KECAMATAN!H24)
A18: 46023 | B18: UPT V | C18: Medan Polonia | D18: =IF(KECAMATAN!C25="","",KECAMATAN!C25) | E18: =IF(KECAMATAN!D25="","",KECAMATAN!D25) | F18: =IF(KECAMATAN!E25="","",KECAMATAN!E25) | G18: =IF(KECAMATAN!F25="","",KECAMATAN!F25) | H18: =IF(KECAMATAN!H25="","",KECAMATAN!H25)
A19: 46023 | B19: UPT V | C19: Medan Maimun | D19: =IF(KECAMATAN!C26="","",KECAMATAN!C26) | E19: =IF(KECAMATAN!D26="","",KECAMATAN!D26) | F19: =IF(KECAMATAN!E26="","",KECAMATAN!E26) | G19: =IF(KECAMATAN!F26="","",KECAMATAN!F26) | H19: =IF(KECAMATAN!H26="","",KECAMATAN!H26)
A20: 46023 | B20: UPT VI | C20: Medan Johor | D20: =IF(KECAMATAN!C28="","",KECAMATAN!C28) | E20: =IF(KECAMATAN!D28="","",KECAMATAN!D28) | F20: =IF(KECAMATAN!E28="","",KECAMATAN!E28) | G20: =IF(KECAMATAN!F28="","",KECAMATAN!F28) | H20: =IF(KECAMATAN!H28="","",KECAMATAN!H28)
A21: 46023 | B21: UPT VI | C21: Medan Selayang | D21: =IF(KECAMATAN!C29="","",KECAMATAN!C29) | E21: =IF(KECAMATAN!D29="","",KECAMATAN!D29) | F21: =IF(KECAMATAN!E29="","",KECAMATAN!E29) | G21: =IF(KECAMATAN!F29="","",KECAMATAN!F29) | H21: =IF(KECAMATAN!H29="","",KECAMATAN!H29)
A22: 46023 | B22: UPT VI | C22: Medan Tuntungan | D22: =IF(KECAMATAN!C30="","",KECAMATAN!C30) | E22: =IF(KECAMATAN!D30="","",KECAMATAN!D30) | F22: =IF(KECAMATAN!E30="","",KECAMATAN!E30) | G22: =IF(KECAMATAN!F30="","",KECAMATAN!F30) | H22: =IF(KECAMATAN!H30="","",KECAMATAN!H30)
A23: 46023 | B23: UPT VII | C23: Medan Belawan | D23: =IF(KECAMATAN!C32="","",KECAMATAN!C32) | E23: =IF(KECAMATAN!D32="","",KECAMATAN!D32) | F23: =IF(KECAMATAN!E32="","",KECAMATAN!E32) | G23: =IF(KECAMATAN!F32="","",KECAMATAN!F32) | H23: =IF(KECAMATAN!H32="","",KECAMATAN!H32)
A24: 46023 | B24: UPT VII | C24: Medan Marelan | D24: =IF(KECAMATAN!C33="","",KECAMATAN!C33) | E24: =IF(KECAMATAN!D33="","",KECAMATAN!D33) | F24: =IF(KECAMATAN!E33="","",KECAMATAN!E33) | G24: =IF(KECAMATAN!F33="","",KECAMATAN!F33) | H24: =IF(KECAMATAN!H33="","",KECAMATAN!H33)
A25: 46023 | B25: UPT VII | C25: Medan Labuhan | D25: =IF(KECAMATAN!C34="","",KECAMATAN!C34) | E25: =IF(KECAMATAN!D34="","",KECAMATAN!D34) | F25: =IF(KECAMATAN!E34="","",KECAMATAN!E34) | G25: =IF(KECAMATAN!F34="","",KECAMATAN!F34) | H25: =IF(KECAMATAN!H34="","",KECAMATAN!H34)
A26: 46024 | B26: UPT I | C26: Medan Amplas | D26: =IF(KECAMATAN!C37="","",KECAMATAN!C37) | E26: =IF(KECAMATAN!D37="","",KECAMATAN!D37) | F26: =IF(KECAMATAN!E37="","",KECAMATAN!E37) | G26: =IF(KECAMATAN!F37="","",KECAMATAN!F37) | H26: =IF(KECAMATAN!H37="","",KECAMATAN!H37)
A27: 46024 | B27: UPT I | C27: Medan Area | D27: =IF(KECAMATAN!C38="","",KECAMATAN!C38) | E27: =IF(KECAMATAN!D38="","",KECAMATAN!D38) | F27: =IF(KECAMATAN!E38="","",KECAMATAN!E38) | G27: =IF(KECAMATAN!F38="","",KECAMATAN!F38) | H27: =IF(KECAMATAN!H38="","",KECAMATAN!H38)
A28: 46024 | B28: UPT I | C28: Medan Kota | D28: =IF(KECAMATAN!C39="","",KECAMATAN!C39) | E28: =IF(KECAMATAN!D39="","",KECAMATAN!D39) | F28: =IF(KECAMATAN!E39="","",KECAMATAN!E39) | G28: =IF(KECAMATAN!F39="","",KECAMATAN!F39) | H28: =IF(KECAMATAN!H39="","",KECAMATAN!H39)
A29: 46024 | B29: UPT II | C29: Medan Tembung | D29: =IF(KECAMATAN!C41="","",KECAMATAN!C41) | E29: =IF(KECAMATAN!D41="","",KECAMATAN!D41) | F29: =IF(KECAMATAN!E41="","",KECAMATAN!E41) | G29: =IF(KECAMATAN!F41="","",KECAMATAN!F41) | H29: =IF(KECAMATAN!H41="","",KECAMATAN!H41)
A30: 46024 | B30: UPT II | C30: Medan Perjuangan | D30: =IF(KECAMATAN!C42="","",KECAMATAN!C42) | E30: =IF(KECAMATAN!D42="","",KECAMATAN!D42) | F30: =IF(KECAMATAN!E42="","",KECAMATAN!E42) | G30: =IF(KECAMATAN!F42="","",KECAMATAN!F42) | H30: =IF(KECAMATAN!H42="","",KECAMATAN!H42)
A31: 46024 | B31: UPT II | C31: Medan Denai | D31: =IF(KECAMATAN!C43="","",KECAMATAN!C43) | E31: =IF(KECAMATAN!D43="","",KECAMATAN!D43) | F31: =IF(KECAMATAN!E43="","",KECAMATAN!E43) | G31: =IF(KECAMATAN!F43="","",KECAMATAN!F43) | H31: =IF(KECAMATAN!H43="","",KECAMATAN!H43)
A32: 46024 | B32: UPT III | C32: Medan Sunggal | D32: =IF(KECAMATAN!C45="","",KECAMATAN!C45) | E32: =IF(KECAMATAN!D45="","",KECAMATAN!D45) | F32: =IF(KECAMATAN!E45="","",KECAMATAN!E45) | G32: =IF(KECAMATAN!F45="","",KECAMATAN!F45) | H32: =IF(KECAMATAN!H45="","",KECAMATAN!H45)
A33: 46024 | B33: UPT III | C33: Medan Petisah | D33: =IF(KECAMATAN!C46="","",KECAMATAN!C46) | E33: =IF(KECAMATAN!D46="","",KECAMATAN!D46) | F33: =IF(KECAMATAN!E46="","",KECAMATAN!E46) | G33: =IF(KECAMATAN!F46="","",KECAMATAN!F46) | H33: =IF(KECAMATAN!H46="","",KECAMATAN!H46)
A34: 46024 | B34: UPT III | C34: Medan Helvetia | D34: =IF(KECAMATAN!C47="","",KECAMATAN!C47) | E34: =IF(KECAMATAN!D47="","",KECAMATAN!D47) | F34: =IF(KECAMATAN!E47="","",KECAMATAN!E47) | G34: =IF(KECAMATAN!F47="","",KECAMATAN!F47) | H34: =IF(KECAMATAN!H47="","",KECAMATAN!H47)
A35: 46024 | B35: UPT IV | C35: Medan Barat | D35: =IF(KECAMATAN!C49="","",KECAMATAN!C49) | E35: =IF(KECAMATAN!D49="","",KECAMATAN!D49) | F35: =IF(KECAMATAN!E49="","",KECAMATAN!E49) | G35: =IF(KECAMATAN!F49="","",KECAMATAN!F49) | H35: =IF(KECAMATAN!H49="","",KECAMATAN!H49)
A36: 46024 | B36: UPT IV | C36: Medan Timur | D36: =IF(KECAMATAN!C50="","",KECAMATAN!C50) | E36: =IF(KECAMATAN!D50="","",KECAMATAN!D50) | F36: =IF(KECAMATAN!E50="","",KECAMATAN!E50) | G36: =IF(KECAMATAN!F50="","",KECAMATAN!F50) | H36: =IF(KECAMATAN!H50="","",KECAMATAN!H50)
A37: 46024 | B37: UPT IV | C37: Medan Deli | D37: =IF(KECAMATAN!C51="","",KECAMATAN!C51) | E37: =IF(KECAMATAN!D51="","",KECAMATAN!D51) | F37: =IF(KECAMATAN!E51="","",KECAMATAN!E51) | G37: =IF(KECAMATAN!F51="","",KECAMATAN!F51) | H37: =IF(KECAMATAN!H51="","",KECAMATAN!H51)
A38: 46024 | B38: UPT V | C38: Medan Baru | D38: =IF(KECAMATAN!C53="","",KECAMATAN!C53) | E38: =IF(KECAMATAN!D53="","",KECAMATAN!D53) | F38: =IF(KECAMATAN!E53="","",KECAMATAN!E53) | G38: =IF(KECAMATAN!F53="","",KECAMATAN!F53) | H38: =IF(KECAMATAN!H53="","",KECAMATAN!H53)
A39: 46024 | B39: UPT V | C39: Medan Polonia | D39: =IF(KECAMATAN!C54="","",KECAMATAN!C54) | E39: =IF(KECAMATAN!D54="","",KECAMATAN!D54) | F39: =IF(KECAMATAN!E54="","",KECAMATAN!E54) | G39: =IF(KECAMATAN!F54="","",KECAMATAN!F54) | H39: =IF(KECAMATAN!H54="","",KECAMATAN!H54)
A40: 46024 | B40: UPT V | C40: Medan Maimun | D40: =IF(KECAMATAN!C55="","",KECAMATAN!C55) | E40: =IF(KECAMATAN!D55="","",KECAMATAN!D55) | F40: =IF(KECAMATAN!E55="","",KECAMATAN!E55) | G40: =IF(KECAMATAN!F55="","",KECAMATAN!F55) | H40: =IF(KECAMATAN!H55="","",KECAMATAN!H55)
A41: 46024 | B41: UPT VI | C41: Medan Johor | D41: =IF(KECAMATAN!C57="","",KECAMATAN!C57) | E41: =IF(KECAMATAN!D57="","",KECAMATAN!D57) | F41: =IF(KECAMATAN!E57="","",KECAMATAN!E57) | G41: =IF(KECAMATAN!F57="","",KECAMATAN!F57) | H41: =IF(KECAMATAN!H57="","",KECAMATAN!H57)
...
